Workbook

Sheet Assumptions
B2: Oracle Corporation (NYSE: ORCL)
B3: Discounted Cash Flow Model - Assumptions
B4: All figures in $ millions unless noted. Fiscal year ends May 31.
B6: LEGEND
B7: Blue text = input you can change
B8: Black text = formula, do not overwrite
B9: Green text = pulled from another tab
B10: Yellow fill = key driver, sanity check before presenting
B12: MARKET DATA | H12: Source / note
B13: Share price ($) | C13: 147 | H13: Update to live price on the day you present
B14: Shares outstanding (mm) | C14: 3023.736 | H14: 10-Q cover page, as of Sept 7 2026
B15: Market capitalisation | C15: =C13*C14 -> 444489.19 | H15: Price x shares
B17: BALANCE SHEET BRIDGE (as of Aug 31 2026)
B18: Notes payable and other borrowings - current | C18: 7625 | H18: 10-Q balance sheet
B19: Notes payable and other borrowings - non-current | C19: 117712 | H19: 10-Q balance sheet
B20: Total debt | C20: =SUM(C18:C19) -> 125337 | H20: Sum of the two lines above
B21: Cash and cash equivalents | C21: 36369 | H21: 10-Q balance sheet
B22: Marketable securities | C22: 708 | H22: 10-Q balance sheet
B23: Net debt | C23: =C20-C21-C22 -> 88260 | H23: Total debt less cash and securities
B24: Preferred stock (6.50% Series D) | C24: 4954 | H24: 10-Q balance sheet
B25: Operating lease liabilities | C25: 34621 | H25: 10-Q Note 6
B26: Finance lease liabilities | C26: 9185 | H26: 10-Q Note 6
B27: Total lease liabilities | C27: =SUM(C25:C26) -> 43806 | H27: Deducted from EV - data centre leases are the business
B29: DISCOUNT RATE
B30: Risk-free rate | C30: 0.042 | H30: 10-year Treasury - update on the day
B31: Equity risk premium | C31: 0.055 | H31: Standard market assumption
B32: Beta | C32: 1.7 | H32: 5Y monthly. Has risen sharply through the 2026 de-rating
B33: Cost of equity | C33: =C30+C32*C31 -> 0.1355 | H33: Rf + Beta x ERP (CAPM)
B34: Pre-tax cost of debt | C34: 0.062 | H34: Reflects BBB- rating. Senior notes carried at $125.0bn trade at $105.7bn fair value, implying a market cost above coupon
B35: After-tax cost of debt | C35: =C34*(1-C42) -> 0.052638 | H35: Pre-tax x (1 - tax rate)
B36: Equity weight | C36: =C15/(C15+C20) -> 0.78004346 | H36: Market cap / (market cap + total debt)
B37: Debt weight | C37: =1-C36 -> 0.21995654 | H37: 1 - equity weight
B38: WACC | C38: =C36*C33+C37*C35 -> 0.11727396 | H38: Weighted average. Sensitivity tab flexes this
B40: OPERATING ASSUMPTIONS
B41: Base year revenue - FY26A | C41: 67400 | H41: FY26 actual, approximate. Verify against the FY26 10-K
B42: Tax rate | C42: 0.151 | H42: Q1 FY27 effective rate, 10-Q Note 8
B43: Useful life of new capex (years) | C43: 6 | H43: 10-Q Note 3: servers and networking equipment, six-year estimated life
B44: D&A on assets already in place | C44: 13400 | H44: Q1 depreciation $3,156mm + intangible amortisation $202mm, annualised
B45: Change in NWC as % of change in revenue | C45: -0.2 | H45: NEGATIVE = source of cash. Deferred revenue rose from $15.4bn to $30.8bn in Q1 as customers prepaid, so working capital funds the business
B46: Terminal exit multiple (EV / EBIT) | C46: 18 | H46: EBIT not EBITDA: D&A is the whole debate here, and an EBITDA multiple would add it back and flatter the business
...

Sheet DCF
B2: Oracle Corporation - Discounted Cash Flow
B3: $ millions. Fiscal year ends May 31. Black cells are formulas - edit inputs on the Assumptions tab.
C5: FY26A | D5: FY27E | E5: FY28E | F5: FY29E | G5: FY30E | H5: FY31E
B7: Stable business revenue | D7: =Assumptions!C50 -> 48000 | E7: =D7*(1+Assumptions!D51) -> 49440 | F7: =E7*(1+Assumptions!E51) -> 50923.2 | G7: =F7*(1+Assumptions!F51) -> 52450.896 | H7: =G7*(1+Assumptions!G51) -> 54024.423
B8: Cloud infrastructure (OCI) revenue | D8: =Assumptions!C52 -> 42000 | E8: =D8*(1+Assumptions!D53) -> 60480 | F8: =E8*(1+Assumptions!E53) -> 76809.6 | G8: =F8*(1+Assumptions!F53) -> 89099.136 | H8: =G8*(1+Assumptions!G53) -> 97118.058
B9: Total revenue | C9: =Assumptions!$C$41 -> 67400 | D9: =D7+D8 -> 90000 | E9: =E7+E8 -> 109920 | F9: =F7+F8 -> 127732.8 | G9: =G7+G8 -> 141550.03 | H9: =H7+H8 -> 151142.48
B10: % growth | D10: =D9/C9-1 -> 0.33531157 | E10: =E9/D9-1 -> 0.22133333 | F10: =F9/E9-1 -> 0.1620524 | G10: =G9/F9-1 -> 0.10817294 | H10: =H9/G9-1 -> 0.067767199
B12: EBIT margin | D12: =Assumptions!C54 -> 0.35 | E12: =Assumptions!D54 -> 0.36 | F12: =Assumptions!E54 -> 0.37 | G12: =Assumptions!F54 -> 0.38 | H12: =Assumptions!G54 -> 0.38
B13: EBIT | D13: =D9*D12 -> 31500 | E13: =E9*E12 -> 39571.2 | F13: =F9*F12 -> 47261.136 | G13: =G9*G12 -> 53789.012 | H13: =H9*H12 -> 57434.143
B14: Less: taxes at effective rate | D14: =-D13*Assumptions!$C$42 -> -4756.5 | E14: =-E13*Assumptions!$C$42 -> -5975.2512 | F14: =-F13*Assumptions!$C$42 -> -7136.4315 | G14: =-G13*Assumptions!$C$42 -> -8122.1408 | H14: =-H13*Assumptions!$C$42 -> -8672.5556
B15: NOPAT (tax-effected EBIT) | D15: =D13+D14 -> 26743.5 | E15: =E13+E14 -> 33595.949 | F15: =F13+F14 -> 40124.704 | G15: =G13+G14 -> 45666.871 | H15: =H13+H14 -> 48761.587
B17: Plus: depreciation and amortisation | D17: =Assumptions!$C$44 -> 13400 | E17: =Assumptions!$C$44+SUM($D$18:D18)/Assumptions!$C$43 -> 28733.333 | F17: =Assumptions!$C$44+SUM($D$18:E18)/Assumptions!$C$43 -> 41733.333 | G17: =Assumptions!$C$44+SUM($D$18:F18)/Assumptions!$C$43 -> 52066.667 | H17: =Assumptions!$C$44+SUM($D$18:G18)/Assumptions!$C$43 -> 61233.333
B18: Less: capital expenditure | D18: =Assumptions!C55 -> 92000 | E18: =Assumptions!D55 -> 78000 | F18: =Assumptions!E55 -> 62000 | G18: =Assumptions!F55 -> 55000 | H18: =Assumptions!G55 -> 55000
B19: Less: change in net working capital | D19: =-(D9-C9)*Assumptions!$C$45 -> 4520 | E19: =-(E9-D9)*Assumptions!$C$45 -> 3984 | F19: =-(F9-E9)*Assumptions!$C$45 -> 3562.56 | G19: =-(G9-F9)*Assumptions!$C$45 -> 2763.4464 | H19: =-(H9-G9)*Assumptions!$C$45 -> 1918.4898
B20: Unlevered free cash flow | D20: =D15+D17-D18+D19 -> -47336.5 | E20: =E15+E17-E18+E19 -> -11686.718 | F20: =F15+F17-F18+F19 -> 23420.598 | G20: =G15+G17-G18+G19 -> 45496.984 | H20: =H15+H17-H18+H19 -> 56913.41
B22: Discount period (mid-year convention not used) | D22: 1 | E22: 2 | F22: 3 | G22: 4 | H22: 5
B23: Discount factor | D23: =1/(1+Assumptions!$C$38)^D22 -> 0.89503563 | E23: =1/(1+Assumptions!$C$38)^E22 -> 0.80108877 | F23: =1/(1+Assumptions!$C$38)^F22 -> 0.71700299 | G23: =1/(1+Assumptions!$C$38)^G22 -> 0.64174322 | H23: =1/(1+Assumptions!$C$38)^H22 -> 0.57438305
B24: PV of unlevered free cash flow | D24: =D20*D23 -> -42367.854 | E24: =E20*E23 -> -9362.0985 | F24: =F20*F23 -> 16792.639 | G24: =G20*G23 -> 29197.381 | H24: =H20*H23 -> 32690.098
B27: TERMINAL VALUE AND EQUITY BRIDGE
B28: FY31E EBIT | C28: =H13 -> 57434.143
B29: Exit multiple (EV / EBIT) | C29: =Assumptions!$C$46 -> 18
B30: Terminal value at FY31 | C30: =C28*C29 -> 1033814.6
B31: PV of terminal value | C31: =C30*H23 -> 593805.56
B32: PV of forecast period cash flows | C32: =SUM(D24:H24) -> 26950.166
B33: Enterprise value | C33: =C31+C32 -> 620755.73
B34: Terminal value as % of enterprise value | C34: =C31/C33 -> 0.95658491 | H34: Name this number before anyone asks. Free cash flow is negative into FY28, so nearly all the value sits in the terminal year.
B35: Less: net debt | C35: =-Assumptions!$C$23 -> -88260
B36: Less: preferred stock | C36: =-Assumptions!$C$24 -> -4954
B37: Less: lease liabilities | C37: =-Assumptions!$C$27 -> -43806
B38: Equity value | C38: =C33+SUM(C35:C37) -> 483735.73
B39: Shares outstanding (mm) | C39: =Assumptions!$C$14 -> 3023.736
B40: Implied value per share | C40: =C38/C39 -> 159.97949
B41: Current share price | C41: =Assumptions!$C$13 -> 147
B42: Implied upside / (downside) | C42: =C40/C41-1 -> 0.088295821

Sheet Sensitivity
B2: Sensitivity - implied value per share
B3: WACC down the side, exit EV/EBIT multiple across the top. Recomputes the full DCF in each cell.
B6: WACC \ Exit multiple | C6: 14 | D6: 16 | E6: 18 | F6: 20 | G6: 22
B7: 0.105 | C7: =((DCF!D20/(1+$B7)^1+DCF!E20/(1+$B7)^2+DCF!F20/(1+$B7)^3+DCF!G20/(1+$B7)^4+DCF!H20/(1+$B7)^5+DCF!H13*C$6/(1+$B7)^5)-Assumptions!$C$23-Assumptions!$C$24-Assumptions!$C$27)/Assumptions!$C$14 -> 126.02518 | D7: =((DCF!D20/(1+$B7)^1+DCF!E20/(1+$B7)^2+DCF!F20/(1+$B7)^3+DCF!G20/(1+$B7)^4+DCF!H20/(1+$B7)^5+DCF!H13*D$6/(1+$B7)^5)-Assumptions!$C$23-Assumptions!$C$24-Assumptions!$C$27)/Assumptions!$C$14 -> 149.08441 | E7: =((DCF!D20/(1+$B7)^1+DCF!E20/(1+$B7)^2+DCF!F20/(1+$B7)^3+DCF!G20/(1+$B7)^4+DCF!H20/(1+$B7)^5+DCF!H13*E$6/(1+$B7)^5)-Assumptions!$C$23-Assumptions!$C$24-Assumptions!$C$27)/Assumptions!$C$14 -> 172.14364 | F7: =((DCF!D20/(1+$B7)^1+DCF!E20/(1+$B7)^2+DCF!F20/(1+$B7)^3+DCF!G20/(1+$B7)^4+DCF!H20/(1+$B7)^5+DCF!H13*F$6/(1+$B7)^5)-Assumptions!$C$23-Assumptions!$C$24-Assumptions!$C$27)/Assumptions!$C$14 -> 195.20288 | G7: =((DCF!D20/(1+$B7)^1+DCF!E20/(1+$B7)^2+DCF!F20/(1+$B7)^3+DCF!G20/(1+$B7)^4+DCF!H20/(1+$B7)^5+DCF!H13*G$6/(1+$B7)^5)-Assumptions!$C$23-Assumptions!$C$24-Assumptions!$C$27)/Assumptions!$C$14 -> 218.26211
B8: 0.11 | C8: =((DCF!D20/(1+$B8)^1+DCF!E20/(1+$B8)^2+DCF!F20/(1+$B8)^3+DCF!G20/(1+$B8)^4+DCF!H20/(1+$B8)^5+DCF!H13*C$6/(1+$B8)^5)-Assumptions!$C$23-Assumptions!$C$24-Assumptions!$C$27)/Assumptions!$C$14 -> 122.00173 | D8: =((DCF!D20/(1+$B8)^1+DCF!E20/(1+$B8)^2+DCF!F20/(1+$B8)^3+DCF!G20/(1+$B8)^4+DCF!H20/(1+$B8)^5+DCF!H13*D$6/(1+$B8)^5)-Assumptions!$C$23-Assumptions!$C$24-Assumptions!$C$27)/Assumptions!$C$14 -> 144.54627 | E8: =((DCF!D20/(1+$B8)^1+DCF!E20/(1+$B8)^2+DCF!F20/(1+$B8)^3+DCF!G20/(1+$B8)^4+DCF!H20/(1+$B8)^5+DCF!H13*E$6/(1+$B8)^5)-Assumptions!$C$23-Assumptions!$C$24-Assumptions!$C$27)/Assumptions!$C$14 -> 167.09081 | F8: =((DCF!D20/(1+$B8)^1+DCF!E20/(1+$B8)^2+DCF!F20/(1+$B8)^3+DCF!G20/(1+$B8)^4+DCF!H20/(1+$B8)^5+DCF!H13*F$6/(1+$B8)^5)-Assumptions!$C$23-Assumptions!$C$24-Assumptions!$C$27)/Assumptions!$C$14 -> 189.63535 | G8: =((DCF!D20/(1+$B8)^1+DCF!E20/(1+$B8)^2+DCF!F20/(1+$B8)^3+DCF!G20/(1+$B8)^4+DCF!H20/(1+$B8)^5+DCF!H13*G$6/(1+$B8)^5)-Assumptions!$C$23-Assumptions!$C$24-Assumptions!$C$27)/Assumptions!$C$14 -> 212.17988
B9: 0.115 | C9: =((DCF!D20/(1+$B9)^1+DCF!E20/(1+$B9)^2+DCF!F20/(1+$B9)^3+DCF!G20/(1+$B9)^4+DCF!H20/(1+$B9)^5+DCF!H13*C$6/(1+$B9)^5)-Assumptions!$C$23-Assumptions!$C$24-Assumptions!$C$27)/Assumptions!$C$14 -> 118.08559 | D9: =((DCF!D20/(1+$B9)^1+DCF!E20/(1+$B9)^2+DCF!F20/(1+$B9)^3+DCF!G20/(1+$B9)^4+DCF!H20/(1+$B9)^5+DCF!H13*D$6/(1+$B9)^5)-Assumptions!$C$23-Assumptions!$C$24-Assumptions!$C$27)/Assumptions!$C$14 -> 140.12916 | E9: =((DCF!D20/(1+$B9)^1+DCF!E20/(1+$B9)^2+DCF!F20/(1+$B9)^3+DCF!G20/(1+$B9)^4+DCF!H20/(1+$B9)^5+DCF!H13*E$6/(1+$B9)^5)-Assumptions!$C$23-Assumptions!$C$24-Assumptions!$C$27)/Assumptions!$C$14 -> 162.17273 | F9: =((DCF!D20/(1+$B9)^1+DCF!E20/(1+$B9)^2+DCF!F20/(1+$B9)^3+DCF!G20/(1+$B9)^4+DCF!H20/(1+$B9)^5+DCF!H13*F$6/(1+$B9)^5)-Assumptions!$C$23-Assumptions!$C$24-Assumptions!$C$27)/Assumptions!$C$14 -> 184.2163 | G9: =((DCF!D20/(1+$B9)^1+DCF!E20/(1+$B9)^2+DCF!F20/(1+$B9)^3+DCF!G20/(1+$B9)^4+DCF!H20/(1+$B9)^5+DCF!H13*G$6/(1+$B9)^5)-Assumptions!$C$23-Assumptions!$C$24-Assumptions!$C$27)/Assumptions!$C$14 -> 206.25987
B10: 0.12 | C10: =((DCF!D20/(1+$B10)^1+DCF!E20/(1+$B10)^2+DCF!F20/(1+$B10)^3+DCF!G20/(1+$B10)^4+DCF!H20/(1+$B10)^5+DCF!H13*C$6/(1+$B10)^5)-Assumptions!$C$23-Assumptions!$C$24-Assumptions!$C$27)/Assumptions!$C$14 -> 114.27347 | D10: =((DCF!D20/(1+$B10)^1+DCF!E20/(1+$B10)^2+DCF!F20/(1+$B10)^3+DCF!G20/(1+$B10)^4+DCF!H20/(1+$B10)^5+DCF!H13*D$6/(1+$B10)^5)-Assumptions!$C$23-Assumptions!$C$24-Assumptions!$C$27)/Assumptions!$C$14 -> 135.82937 | E10: =((DCF!D20/(1+$B10)^1+DCF!E20/(1+$B10)^2+DCF!F20/(1+$B10)^3+DCF!G20/(1+$B10)^4+DCF!H20/(1+$B10)^5+DCF!H13*E$6/(1+$B10)^5)-Assumptions!$C$23-Assumptions!$C$24-Assumptions!$C$27)/Assumptions!$C$14 -> 157.38527 | F10: =((DCF!D20/(1+$B10)^1+DCF!E20/(1+$B10)^2+DCF!F20/(1+$B10)^3+DCF!G20/(1+$B10)^4+DCF!H20/(1+$B10)^5+DCF!H13*F$6/(1+$B10)^5)-Assumptions!$C$23-Assumptions!$C$24-Assumptions!$C$27)/Assumptions!$C$14 -> 178.94117 | G10: =((DCF!D20/(1+$B10)^1+DCF!E20/(1+$B10)^2+DCF!F20/(1+$B10)^3+DCF!G20/(1+$B10)^4+DCF!H20/(1+$B10)^5+DCF!H13*G$6/(1+$B10)^5)-Assumptions!$C$23-Assumptions!$C$24-Assumptions!$C$27)/Assumptions!$C$14 -> 200.49707
B11: 0.125 | C11: =((DCF!D20/(1+$B11)^1+DCF!E20/(1+$B11)^2+DCF!F20/(1+$B11)^3+DCF!G20/(1+$B11)^4+DCF!H20/(1+$B11)^5+DCF!H13*C$6/(1+$B11)^5)-Assumptions!$C$23-Assumptions!$C$24-Assumptions!$C$27)/Assumptions!$C$14 -> 110.56217 | D11: =((DCF!D20/(1+$B11)^1+DCF!E20/(1+$B11)^2+DCF!F20/(1+$B11)^3+DCF!G20/(1+$B11)^4+DCF!H20/(1+$B11)^5+DCF!H13*D$6/(1+$B11)^5)-Assumptions!$C$23-Assumptions!$C$24-Assumptions!$C$27)/Assumptions!$C$14 -> 131.64329 | E11: =((DCF!D20/(1+$B11)^1+DCF!E20/(1+$B11)^2+DCF!F20/(1+$B11)^3+DCF!G20/(1+$B11)^4+DCF!H20/(1+$B11)^5+DCF!H13*E$6/(1+$B11)^5)-Assumptions!$C$23-Assumptions!$C$24-Assumptions!$C$27)/Assumptions!$C$14 -> 152.7244 | F11: =((DCF!D20/(1+$B11)^1+DCF!E20/(1+$B11)^2+DCF!F20/(1+$B11)^3+DCF!G20/(1+$B11)^4+DCF!H20/(1+$B11)^5+DCF!H13*F$6/(1+$B11)^5)-Assumptions!$C$23-Assumptions!$C$24-Assumptions!$C$27)/Assumptions!$C$14 -> 173.80552 | G11: =((DCF!D20/(1+$B11)^1+DCF!E20/(1+$B11)^2+DCF!F20/(1+$B11)^3+DCF!G20/(1+$B11)^4+DCF!H20/(1+$B11)^5+DCF!H13*G$6/(1+$B11)^5)-Assumptions!$C$23-Assumptions!$C$24-Assumptions!$C$27)/Assumptions!$C$14 -> 194.88664
B14: Grid is centred on the WACC the Assumptions tab computes (~11.7%, driven by the 1.7 beta). Highlighted cell is closest to the base case.
B15: Read the range, not the point estimate. This spread is the honest answer to 'how confident are you?'

Sheet SOTP
B2: Sum of the Parts - what are you paying for OCI?
B3: Back out the stable business at a conservative multiple and see what the market implies for cloud infrastructure plus the backlog.
B5: STABLE BUSINESS (Q1 FY27 actuals, annualised) | C5: Q1 FY27 | D5: Annualised
B6: Software licence | C6: 655 | D6: =C6*4 -> 2620
B7: Software support | C7: 4895 | D7: =C7*4 -> 19580
B8: Cloud applications (SaaS) | C8: 4219 | D8: =C8*4 -> 16876
B9: Hardware | C9: 774 | D9: =C9*4 -> 3096
B10: Services | C10: 1414 | D10: =C10*4 -> 5656
B11: Total stable revenue | C11: =SUM(C6:C10) -> 11957 | D11: =SUM(D6:D10) -> 47828 | E11: Source: 10-Q revenue-by-offering tables, quarter ended Aug 31 2026
B12: Multiple applied (EV / revenue) | C12: 5 | E12: Conservative for a high-margin annuity. Software support declined only 1% YoY.
B13: Implied value of stable business | C13: =D11*C12 -> 239140
B15: IMPLIED VALUE OF CLOUD INFRASTRUCTURE
B16: Enterprise value (incl. leases) | C16: =Assumptions!$C$15+Assumptions!$C$23+Assumptions!$C$24+Assumptions!$C$27 -> 581509.19
B17: Less: value of stable business | C17: =-C13 -> -239140
B18: Implied value of OCI + backlog | C18: =C16+C17 -> 342369.19
B20: SANITY CHECKS
B21: OCI revenue, Q1 FY27 annualised | C21: =7388*4 -> 29552
B22: Implied EV / OCI revenue | C22: =C18/C21 -> 11.585314 | E22: For a business that grew 121% year over year
B23: Remaining performance obligations | C23: 664000 | E23: 10-Q Note 1. Up from $455bn a year ago.
B24: Implied value as % of contracted backlog | C24: =C18/C23 -> 0.51561625 | E24: This is the money line. State it out loud in the pitch.

Sheet Summary
B2: Valuation Summary
B3: Three methods. Your target should sit where they overlap, not on whichever is highest.
B5: Method | C5: Implied price | D5: Upside | E5: How you defend it in one sentence
B6: Forward P/E - 20x | C6: =8.1*20 -> 162 | D6: =C6/Assumptions!$C$13-1 -> 0.10204082 | E6: Still a discount to Microsoft at 26x and Alphabet at 22x despite faster growth.
B7: Forward P/E - 22x | C7: =8.1*22 -> 178.2 | D7: =C7/Assumptions!$C$13-1 -> 0.2122449 | E7: Parity with Alphabet. FY27 guidance is $8.10 of adjusted EPS.
B8: Discounted cash flow | C8: =DCF!C40 -> 159.97949 | D8: =C8/Assumptions!$C$13-1 -> 0.088295821 | E8: Terminal-heavy by construction, so weight it alongside the others rather than leading with it.
B9: Sum of the parts | E9: Not a price target - it shows what you are paying for the backlog. Quote the % of face value.
B10: Street consensus | C10: 239 | D10: =C10/Assumptions!$C$13-1 -> 0.62585034 | E10: Landing below consensus signals you priced the concentration and leverage risk yourself.
B11: YOUR TARGET | C11: 170 | D11: =C11/Assumptions!$C$13-1 -> 0.15646259 | E11: Set this yourself once you have looked at the range above.
B14: IF THEY ASK WHY THE DCF IS TERMINAL-HEAVY
B15: Say: free cash flow is negative through FY28 because Oracle is spending $90-95bn of capex against
B16: contracted revenue, so almost all the value lands in the terminal year. That means the output is really
B17: my exit multiple. That is why I weight the comps and the sum of the parts equally rather than leading with the DCF.
